<?xml version="1.0"?>
<robot name="shibot_inu">
    <material name="Gray">
        <color rgba="0.2 0.2 0.2 1.0"/>
    </material>
    <material name="Orange">
        <color rgba="1.0 0.423529411765 0.0392156862745 1.0"/>
    </material>
    <material name="Blue">
        <color rgba="0.5 0.7 1.0 1.0"/>
    </material>

    <link name="robot_base">
        <inertial>
            <origin xyz="0 0 0" rpy="0 0 0"/>
            <mass value="1.0"/>
            <inertia ixx="0.05" ixy="0" ixz="0" iyy="0.05" iyz="0" izz="0.05"/>
        </inertial>
        <visual>
            <geometry>
                <mesh filename="meshes/robot_base.stl" scale="0.001 0.001 0.001"/>
            </geometry>
            <material name="Gray"/>
        </visual>
        <collision>
            <geometry>
                <mesh filename="meshes/robot_base.stl" scale="0.001 0.001 0.001"/>
            </geometry>
        </collision>
    </link>

    <link name="l_hip_leg1">
        <inertial>
            <origin xyz="0 0 0" rpy="0 0 0"/>
            <mass value="1"/>
            <inertia ixx="0.005" ixy="0" ixz="0" iyy="0.005" iyz="0" izz="0.005"/>
        </inertial>
        <visual>
            <geometry>
                <mesh filename="meshes/l_hip_leg1.stl" scale="0.001 0.001 0.001"/>
            </geometry>
            <origin rpy="0 0 0" xyz="0 0 0"/>
            <material name="Orange"/>
        </visual>
        <collision>
            <geometry>
                <mesh filename="meshes/l_hip_leg1.stl" scale="0.001 0.001 0.001"/>
            </geometry>
        </collision>
    </link>
    <link name="r_hip_leg1">
        <inertial>
            <origin xyz="0 0 0" rpy="0 0 0"/>
            <mass value="1"/>
            <inertia ixx="0.005" ixy="0" ixz="0" iyy="0.005" iyz="0" izz="0.005"/>
        </inertial>
        <visual>
            <geometry>
                <mesh filename="meshes/r_hip_leg1.stl" scale="0.001 0.001 0.001"/>
            </geometry>
            <origin rpy="0 0 0" xyz="0 0 0"/>
            <material name="Orange"/>
        </visual>
        <collision>
            <geometry>
                <mesh filename="meshes/r_hip_leg1.stl" scale="0.001 0.001 0.001"/>
            </geometry>
        </collision>
    </link>
    <link name="l_hip_leg2">
        <inertial>
            <origin xyz="0 0 0" rpy="0 0 0"/>
            <mass value="1"/>
            <inertia ixx="0.005" ixy="0" ixz="0" iyy="0.005" iyz="0" izz="0.005"/>
        </inertial>
        <visual>
            <geometry>
                <mesh filename="meshes/l_hip_leg2.stl" scale="0.001 0.001 0.001"/>
            </geometry>
            <origin rpy="0 0 0" xyz="0 0 0"/>
            <material name="Orange"/>
        </visual>
        <collision>
            <geometry>
                <mesh filename="meshes/l_hip_leg2.stl" scale="0.001 0.001 0.001"/>
            </geometry>
        </collision>
    </link>
    <link name="r_hip_leg2">
        <inertial>
            <origin xyz="0 0 0" rpy="0 0 0"/>
            <mass value="1"/>
            <inertia ixx="0.005" ixy="0" ixz="0" iyy="0.005" iyz="0" izz="0.005"/>
        </inertial>
        <visual>
            <geometry>
                <mesh filename="meshes/r_hip_leg2.stl" scale="0.001 0.001 0.001"/>
            </geometry>
            <origin rpy="0 0 0" xyz="0 0 0"/>
            <material name="Orange"/>
        </visual>
        <collision>
            <geometry>
                <mesh filename="meshes/r_hip_leg2.stl" scale="0.001 0.001 0.001"/>
            </geometry>
        </collision>
    </link>

    <link name="l_foot1">
        <inertial>
            <origin xyz="0 0 0" rpy="0 0 0"/>
            <mass value="1"/>
            <inertia ixx="0.002" ixy="0" ixz="0" iyy="0.002" iyz="0" izz="0.002"/>
        </inertial>
        <visual>
            <geometry>
                <mesh filename="meshes/l_foot1.stl" scale="0.001 0.001 0.001"/>
            </geometry>
            <origin rpy="0 0 0" xyz="0 0 0"/>
            <material name="Gray"/>
        </visual>
        <collision>
            <geometry>
                <mesh filename="meshes/l_foot1.stl" scale="0.001 0.001 0.001"/>
            </geometry>
            <surface>
                <friction>
                    <ode>
                        <mu>0.35</mu>
                        <mu2>0.35</mu2>
                    </ode>
                </friction>
            </surface>
        </collision>
    </link>
    <link name="r_foot1">
        <inertial>
            <origin xyz="0 0 0" rpy="0 0 0"/>
            <mass value="1"/>
            <inertia ixx="0.002" ixy="0" ixz="0" iyy="0.002" iyz="0" izz="0.002"/>
        </inertial>
        <visual>
            <geometry>
                <mesh filename="meshes/r_foot1.stl" scale="0.001 0.001 0.001"/>
            </geometry>
            <origin rpy="0 0 0" xyz="0 0 0"/>
            <material name="Gray"/>
        </visual>
        <collision>
            <geometry>
                <mesh filename="meshes/r_foot1.stl" scale="0.001 0.001 0.001"/>
            </geometry>
            <surface>
                <friction>
                    <ode>
                        <mu>0.35</mu>
                        <mu2>0.35</mu2>
                    </ode>
                </friction>
            </surface>
        </collision>
    </link>
    <link name="l_foot2">
        <inertial>
            <origin xyz="0 0 0" rpy="0 0 0"/>
            <mass value="1"/>
            <inertia ixx="0.002" ixy="0" ixz="0" iyy="0.002" iyz="0" izz="0.002"/>
        </inertial>
        <visual>
            <geometry>
                <mesh filename="meshes/l_foot2.stl" scale="0.001 0.001 0.001"/>
            </geometry>
            <origin rpy="0 0 0" xyz="0 0 0"/>
            <material name="Gray"/>
        </visual>
        <collision>
            <geometry>
                <mesh filename="meshes/l_foot2.stl" scale="0.001 0.001 0.001"/>
            </geometry>
            <surface>
                <friction>
                    <ode>
                        <mu>0.35</mu>
                        <mu2>0.35</mu2>
                    </ode>
                </friction>
            </surface>
        </collision>
    </link>
    <link name="r_foot2">
        <inertial>
            <origin xyz="0 0 0" rpy="0 0 0"/>
            <mass value="1"/>
            <inertia ixx="0.002" ixy="0" ixz="0" iyy="0.002" iyz="0" izz="0.002"/>
        </inertial>
        <visual>
            <geometry>
                <mesh filename="meshes/r_foot2.stl" scale="0.001 0.001 0.001"/>
            </geometry>
            <origin rpy="0 0 0" xyz="0 0 0"/>
            <material name="Gray"/>
        </visual>
        <collision>
            <geometry>
                <mesh filename="meshes/r_foot2.stl" scale="0.001 0.001 0.001"/>
            </geometry>
            <surface>
                <friction>
                    <ode>
                        <mu>0.35</mu>
                        <mu2>0.35</mu2>
                    </ode>
                </friction>
            </surface>
        </collision>
    </link>

    <joint name="l_hip_leg1_joint" type="revolute">
        <origin xyz="-0.12 -0.06 -0.006" />
        <parent link="robot_base" />
        <child link="l_hip_leg1" />
        <axis xyz="0 1 0" />
        <limit lower="-2.0" upper="2.0" effort="2" velocity="11.0"/>
    </joint>
    <joint name="r_hip_leg1_joint" type="revolute">
        <origin xyz="-0.12 0.06 -0.006" />
        <parent link="robot_base" />
        <child link="r_hip_leg1" />
        <axis xyz="0 1 0" />
        <limit lower="-2.0" upper="2.0" effort="2" velocity="11.0"/>
    </joint>
    <joint name="l_hip_leg2_joint" type="revolute">
        <origin xyz="0.09 -0.06 -0.006" />
        <parent link="robot_base" />
        <child link="l_hip_leg2" />
        <axis xyz="0 1 0" />
        <limit lower="-2.0" upper="2.0" effort="2" velocity="11.0"/>
    </joint>
    <joint name="r_hip_leg2_joint" type="revolute">
        <origin xyz="0.09 0.06 -0.006" />
        <parent link="robot_base" />
        <child link="r_hip_leg2" />
        <axis xyz="0 1 0" />
        <limit lower="-2.0" upper="2.0" effort="2" velocity="11.0"/>
    </joint>

    <joint name="l_foot_joint1" type="revolute">
        <origin xyz="0.1 0 -0.027" />
        <parent link="l_hip_leg1" />
        <child link="l_foot1" />
        <axis xyz="0 1 0" />
        <limit lower="-3.14" upper="0" effort="5" velocity="11.0"/>
    </joint>
    <joint name="r_foot_joint1" type="revolute">
        <origin xyz="0.1 0 -0.027" />
        <parent link="r_hip_leg1" />
        <child link="r_foot1" />
        <axis xyz="0 1 0" />
        <limit lower="-3.14" upper="0" effort="5" velocity="11.0"/>
    </joint>
    <joint name="l_foot_joint2" type="revolute">
        <origin xyz="0.1 0 -0.027" />
        <parent link="l_hip_leg2" />
        <child link="l_foot2" />
        <axis xyz="0 1 0" />
        <limit lower="-3.14" upper="0" effort="5" velocity="11.0"/>
    </joint>
    <joint name="r_foot_joint2" type="revolute">
        <origin xyz="0.1 0 -0.027" />
        <parent link="r_hip_leg2" />
        <child link="r_foot2" />
        <axis xyz="0 1 0" />
        <limit lower="-3.14" upper="0" effort="5" velocity="11.0"/>
    </joint>
</robot>